Workbook

Sheet Overall Farm
A1: Burkina Faso Sustainable Farm (Cohort 2025-2026)
A7: equivalence between euro and xof: 1€ = ... xof | C7: 655
A9: 1 million xof = ...€ | C9: 1600
B13: Simulation | C13: Farm
A15: Location | B15: software simulation | C15: Banfora
A16: Size (hectare) | B16: 2 | C16: 2
A17: Investment needed (Xof) | B17: // | C17: 65597254
A18: Investment needed (Euro) | B18: // | C18: =D73+D81+D87+D91+D95+D99+D106 -> 100059.34
A20: Comments
A22: Simulation | B22: phase of simulating the whole farm workflow
A23: Farm | B23: phase during which we have a sustainable farm in Koubri set to produce mangoes permanently that will be dried and sent to Germany
A26: Parts of the Farm | G26: Descriptions
A28: Energy Supply system (Solar PV power plant,Solar Tracking) | G28: The solar PV power plant sufficiently provide the farm in green energy
G29: Improve energy production efficiency by tracking sun rotation
A30: Irrigation system | G30: Automatic irrigation to optimize water usage in the farm
A31: Crop Storage (Smart Dryer) | G31: The Smart Food Dryer efficiently dries fruits and vegetables, preserving nutrients
A32: Fencing and Security (Face Recognition) | G32: Secure the farm by managing access to critical areas, personnal management(attendance), classify plants as useful or unwanted
A33: Visitors Management (No Reesa) | G33: An application that provides a translation of the farm services from Moore to German
A34: Processing Machines | G34: Idendify the farm needs in terms of machine
A35: Plants | G35: Know which variety and which amount of mangoes we should have in our farm
A38: Stage of the Project | B38: =A26 -> Parts of the Farm | C38: key figures from subpart | E38: =A15 -> Location
A40: simulation | B40: =A28 -> Energy Supply system (Solar PV power plant,Solar Tracking) | C40: Investment needed (xof) | D40: // | E40: software simulation
C41: Input needed | D41: Sun
C42: Output | D42: Electricy
C43: Infineon chips | D43: PSoC™ Edge AI
D44: XENSIV™ TLE4971
D45: XENSIV™ PAS CO₂ sensor
D46: XENSIV™ 60GHz radar sensor
D47: XENSIV™ DPS310
B48: =A30 -> Irrigation system | C48: Investment needed (xof) | D48: //
C49: Input needed | D49: water
C50: Output | D50: smart irrigation
C51: Infineon chips | D51: capteur XENSIV
D52: Bluetoofh Low Energy
D53: PSoC CAPSENSE
B54: =A31 -> Crop Storage (Smart Dryer) | C54: Investment needed | D54: //
C55: Input needed | D55: Mangoes
C56: Output | D56: Dried mangoes
C57: Infineon chips | D57: //
B58: =A32 -> Fencing and Security (Face Recognition) | C58: Investment needed | D58: //
...

Sheet Plants(Zalka)
A1: Table 1: Farm sizing | P1: Present value of future cash flows
A2: Variety of mango | B2: Number of trees | C2: Tree-to-tree spacing | D2: Output(Kg) | P2: Years | Q2: Cashflow | R2: Discount Factor | S2: Discounted Cashflow
A3: Kent | B3: 200 | C3: 8meters | D3: 40000 | P3: 1 | Q3: =$R$20 -> 33210.8 | R3: =1/(1+$R$21)^P3 -> 0.92592593 | S3: =Q3*R3 -> 30750.741
A4: Keitt | B4: 200 | C4: 8meters | D4: 44000 | P4: 2 | Q4: =$R$20 -> 33210.8 | R4: =1/(1+$R$21)^P4 -> 0.85733882 | S4: =Q4*R4 -> 28472.908
A5: Amelie | B5: 200 | C5: 8meters | D5: 32000 | P5: 3 | Q5: =$R$20 -> 33210.8 | R5: =1/(1+$R$21)^P5 -> 0.79383224 | S5: =Q5*R5 -> 26363.804
P6: 4 | Q6: =$R$20 -> 33210.8 | R6: =1/(1+$R$21)^P6 -> 0.73502985 | S6: =Q6*R6 -> 24410.929
P7: 5 | Q7: =$R$20 -> 33210.8 | R7: =1/(1+$R$21)^P7 -> 0.6805832 | S7: =Q7*R7 -> 22602.712
F8: Table 3: Monitoring the health of trees and fruit | P8: 6 | Q8: =$R$20 -> 33210.8 | R8: =1/(1+$R$21)^P8 -> 0.63016963 | S8: =Q8*R8 -> 20928.437
F9: Health Level (%) | G9: Observation | P9: 7 | Q9: =$R$20 -> 33210.8 | R9: =1/(1+$R$21)^P9 -> 0.5834904 | S9: =Q9*R9 -> 19378.183
B10: Table 2: water requirement per month in L | F10: 0% - 20% | G10: Trees and fruit under stress, risk of high yield loss | P10: 8 | Q10: =$R$20 -> 33210.8 | R10: =1/(1+$R$21)^P10 -> 0.54026888 | S10: =Q10*R10 -> 17942.762
B11: water requirement | C11: all varieties combined | F11: 21 - 40% | G11: Weakened trees, affected fruit development | P11: 9 | Q11: =$R$20 -> 33210.8 | R11: =1/(1+$R$21)^P11 -> 0.50024897 | S11: =Q11*R11 -> 16613.668
B12: water requirement per tree | C12: 20 m³ per day | F12: 41 - 60% | G12: Trees in average health, fruit growing normally | P12: 10 | Q12: =$R$20 -> 33210.8 | R12: =1/(1+$R$21)^P12 -> 0.46319349 | S12: =Q12*R12 -> 15383.026
F13: 61 - 80% | G13: Healthy trees, high-quality fruit
F14: 81 - 100% | G14: Very healthy trees, excellent fruit
Q18: Cashflow Parameters
Q19: annual income | R19: =L26/5 -> 39917.8
Q20: cashflow | R20: =R19-L23 -> 33210.8
A21: Table 4: Equipment Pricing (Fixed cost) | D21: Table 5: Variable costs | K21: Financial Analysis | Q21: Discount factor | R21: 0.08
A22: Equipment | B22: 2 ha | D22: Equipment | E22: Description | G22: Table 6: Purchase price of plots | K22: Initial equipment cost on 5years | L22: 22865
A23: Tractor / Power tiller | B23: 6860 | D23: Maintenance (routine) | E23: Small, regular repairs on equipment | G23: Surface area | H23: 2 ha | K23: Operational Cost per year | L23: 6707
A24: Motor pump / Irrigation | B24: 4573 | D24: Packaging materials | E24: Bags, crates, and other packaging | G24: Land | H24: 115867 | K24: Operational Cost per 5 years | L24: 33534
A25: Planting and harvesting tools | B25: 1829 | D25: Irrigation cost | E25: Cost of pumped or purchased water | G25: Administrative Fees | H25: 5793 | K25: Investment Cost per 5 years | L25: 56399
A26: Post-harvest equipment | B26: 2286 | D26: Fuel | E26: Fuel for tractor, motor pump, and irrigation | G26: Labor over 5 years | H26: 30490 | K26: Total income over 5 years | L26: 199589
A27: Inputs (fertilizers, seeds) | B27: 3814 | D27: Transport costs | E27: Transport of produce to markets or collection centers | G27: Equipment | H27: 19362 | K27: plots Investissement total | L27: 171445.03
A28: Total Price of equipment | B28: 15548 | D28: Seasonal labor | E28: Temporary labor for planting, weeding, and harvesting | G28: Total Investment | H28: 171512 | K28: ROI (%) | L28: 16.34%
K29: Payback period (years) | L29: 4.3
A33: Depreciation of machinery | F33: Cost per kg of Mango
A34: Item | B34: Total Value | C34: Lifespan (years) | D34: Annual Cost | F34: Variety | G34: Yield 2 ha (kg/year) | H34: Cost per kg
A35: Machinery and equipment | B35: 15548 | C35: 5 | D35: =B35/C35 -> 3109.6 | F35: Keitt | G35: 67.06 | H35: =D37/G35 -> 146.38533
A36: Operational Costs | B36: 6707 | C36: 1 | D36: =B36/C36 -> 6707
A37: Total Annual Cost | B37: ... | C37: ... | D37: =D36+D35 -> 9816.6
F38: Cost per Mango
E39: ` | F39: Average Weight (kg) | G39: Number of Mangoes/year | H39: Cost per Mango
A40: Table 8: final estimate for a 2-hectare farm | F40: 0.25 | G40: =G35/F40 -> 268.24 | H40: 53.8
F41: 0.3 | G41: 224 | H41: 64.6
A42: Step | B42: Description | C42: Values
A43: Number of Trees to Plant | B43: Total trees on 2 hectares | C43: 200 trees
B44: Spacing | C44: 8 meters between trees
A45: Planting Period | B45: Best planting time | C45: Beginning of the rainy season
B46: Growth phases | C46: Years 0 to 2: establishment Years 3 to 5: gradual production Years 5 to 7: full production
...

Sheet Irrigation System(Arcus)
A2: Summary Table – 2 Hectares Smart Irrigation System
A3: Parameters | B3: Symbol / Unit | C3: Value | D3: Comment / Description | F3: Definitions | I3: Input parameters and definitions | P3: Regional Irrigation Energy & Cost Comparison (180 days)
A4: Area | B4: A [ha] | C4: 2 | D4: Cultivated surface | F4: Term / Abbreviation | G4: Definition | I4: Parameter | J4: Symbol | K4: Unit | L4: Value | M4: Description | P4: Region | Q4: Daily Water (m³/day) | R4: Energy (kWh/day) | S4: Annual Energy (kWh/year) | T4: Annual Cost (CFA/year) | U4: Dry days per year
A5: Number of trees | B5: N [trees] | C5: 200 | D5: 8 m spacing | F5: Area [ha] | G5: Cultivated surface area in hectares | I5: Area (ha) | J5: A | K5: ha | L5: 2 | M5: Total cultivated area | P5: Koubri | Q5: 20 | R5: 2.2 | S5: =R5*U5 -> 539 | T5: =S5*150 -> 80850 | U5: 245
A6: Water demand per tree | B6: Wₜ [L/day] | C6: 100 | D6: Mature mango tree | F6: Trees | G6: Number of mango trees | I6: Spacing | J6: S | K6: m | L6: 8 | M6: Distance between mango trees | P6: Bobo | Q6: 14 | R6: 1.54 | S6: =R6*U6 -> 331.1 | T6: =S6*150 -> 49665 | U6: 215
A7: Total water demand | B7: [m³/day] | C7: 20 | D7: 200 × 100 / 1000 | F7: Water demand [m³/d] | G7: Required irrigation water per day in cubic meters | I7: Number of trees | J7: N | K7: tree | L7: 200 | M7: Based on 8 m spacing (2 ha → 200 trees) | P7: Banfora | Q7: 12 | R7: 1.32 | S7: =R7*U7 -> 244.2 | T7: =S7*150 -> 36630 | U7: 185
A8: Irrigation hours/day | B8: t [h/day] | C8: 5 | D8: Daily irrigation duration | F8: Q [m³/h] | G8: Flow rate in cubic meters per hour | I8: Water demand per tree | J8: Wt | K8: L/day | L8: 100 | M8: Estimated for mature mango trees in dry season | P8: Kaya | Q8: 26 | R8: 2.86 | S8: =R8*U8 -> 786.5 | T8: =S8*150 -> 117975 | U8: 275
A9: Flow rate | B9: Q [m³/h] | C9: 4 | D9: 20 ÷ 5 | F9: Q [L/min] | G9: Flow rate in liters per minute | I9: Conversion factor | J9: - | K9: - | L9: 1000 | M9: Liters to cubic meters | P9: Ouahigouya | Q9: 30 | R9: 3.3 | S9: =R9*U9 -> 907.5 | T9: =S9*150 -> 136125 | U9: 275
A10: Hydraulic power | B10: Pₕ [kW] | C10: 0.378 | D10: (ρ × g × Q × H)/3.6×10⁶ | F10: P_h [kW] | G10: Hydraulic pump power | I10: Irrigation hours/day | J10: t | K10: h/day | L10: 5 | M10: Daily irrigation duration
A11: Electric power | B11: Pₑ [kW] | C11: 0.44 | D11: Considering 85% efficiency | F11: P_e [kW] | G11: Electric pump power required | I11: System efficiency | J11: η | K11: % | L11: 85 | M11: Includes hydraulic & electrical losses | P11: Solar Savings vs Grid Cost | Y11: Data | Z11: Source | AA11: Link
A12: PV size | B12: [kWp] | C12: 0.52 | D12: For 1 kW pump use | F12: PV [kWp] | G12: Photovoltaic power peak required | I12: Pump head | J12: H | K12: m | L12: 20 | M12: Static + dynamic head estimation | P12: Region | Q12: Grid Cost (CFA/year) | R12: Solar OPEX (CFA/year) | S12: Annual Savings (CFA/year) | Y12: Burkina rainfall & seasonal calendar | Z12: DG-Météo Burkina Faso | AA12: https://www.meteo.bf/
A13: PV panels | B13: [units] | C13: 4 | D13: 400 Wp each | F13: MPPT | G13: Maximum Power Point Tracking (PV controller technology) | I13: Tank capacity | J13: - | K13: m³ | L13: 30 | M13: Storage for 1.5-day buffer (30 m³ for 2-ha orchard) | P13: Koubri | Q13: =T5 -> 80850 | R13: 32750 | S13: =Q13-R13 -> 48100 | Y13: Sahel rainfall & ET₀ | Z13: AGRHYMET Regional Centre | AA13: https://www.agrhymet.ne/
A14: Tank capacity | B14: [m³] | C14: 30 | D14: 1.5-day storage buffer | F14: Smart add-ons | G14: IoT devices, sensors, controllers, and communication modules for smart irrigation management (e.g., soil moisture sensors, flow meters, GSM/Wi-Fi monitoring, automated scheduling) | I14: Water density | J14: ρ | K14: kg/m³ | L14: 1000 | M14: Density of water | P14: Bobo | Q14: =T6 -> 49665 | R14: 32750 | S14: =Q14-R14 -> 16915 | Y14: ET₀ & crop coefficients | Z14: FAO ClimWat / AquaCrop | AA14: https://www.fao.org/land-water/databases-and-software/climwat-for-cropwat/en/
A15: Total investment cost | B15: [€] | C15: =E33 -> 5420 | D15: CAPEX (equipment only) | I15: Gravity | J15: g | K15: m/s² | L15: 9.81 | M15: Acceleration due to gravity | P15: Banfora | Q15: =T7 -> 36630 | R15: 32750 | S15: =Q15-R15 -> 3880 | Y15: Mango water use | Z15: FAO Irrigation Paper 56 | AA15: https://www.fao.org/3/x0490e/x0490e0i.htm
A16: Payback period | B16: [years] | C16: =H30 -> 7.2266667 | I16: Flow rate | J16: Q | K16: m³/h | L16: - | M16: Hourly discharge to meet water demand | P16: Kaya | Q16: =T8 -> 117975 | R16: 32750 | S16: =Q16-R16 -> 85225 | Y16: Sahel dry-season climate maps | Z16: CILSS | AA16: https://cilss.int/
A17: Annual savings | B17: [€] | C17: 800 | D17: Water & fuel cost savings | P17: Ouahigouya | Q17: =T9 -> 136125 | R17: 32750 | S17: =Q17-R17 -> 103375 | Y17: Solar pumping energy cost | Z17: ECREEE / ECOWAS energy data | AA17: https://www.ecowas.int/
A18: Project lifetime | B18: [years] | C18: 25 | D18: PV and system lifespan
A20: Calculation with 2 hectares scenarios
A21: Scenarios | B21: Area (ha) | C21: Trees | D21: Water demand (m³ /day) | E21: Water demand (m³/ week) | F21: Flow Q (m³/h) | G21: Flow Q (L/min) | H21: Hydraulic power P_h (kW) | I21: Electric power P_e (kW) | J21: Pump required (kWh) | K21: PV size (kWp) | L21: PV Panels (400 Wp) | M21: Investment Cost | N21: Payback period
A22: 2 hectares | B22: 2 | C22: =B22*100 -> 200 | D22: =(C22*100)/1000 -> 20 | E22: =D22*7 -> 140 | F22: =D22/5 -> 4 | G22: =(F22*L9)/60 -> 66.666667 | H22: =0.0027*F22*35 -> 0.378 | I22: =H22/0.85 -> 0.44470588 | J22: =I22 -> 0.44470588 | K22: =J22/0.85 -> 0.52318339 | L22: 4 | M22: =E33 -> 5420 | N22: =H30 -> 7.2266667
A25: Cost calculations | G25: Financial analysis | M25: Seasonal Irrigation Plan (Burkina Faso – Mango Zone) | V25: Seasonal Water Demand | AA25: SWOT Analysis – 2-hectare Solar-Powered Smart Irrigation System
A26: Material | B26: Unit | C26: Quantity | D26: Unit cost (CFA) | E26: Total cost (CFA) | G26: Parameter | H26: Value | I26: Unit | J26: Comment | M26: Season | N26: Period (months) | O26: Avg monthly rainfall (mm) | P26: Irrigation frequency (events/week) | Q26: Daily water demand (m³/day) | R26: Weekly water demand (m³/week) | S26: Notes | T26: Source / Reference | V26: Season | W26: fₛ | X26: Water demand (m³/day) | Y26: Weekly demand (m³/week)
A27: Tank (30 m³) | B27: unit | C27: 1 | D27: 1800 | E27: =D27*C27 -> 1800 | G27: Annual water cost saved | H27: 800 | I27: €/year | J27: Estimated savings vs. manual irrigation labor and diesel pump use | M27: Rainy (Hivernage) | N27: May – October | O27: 120–300 | P27: 1 | Q27: 6–8 | R27: 42–56 | S27: Rain-fed; minimal irrigation needed | T27: DG-Météo Burkina Faso (2023), AGRHYMET | V27: Rainy (May–Oct) | W27: 0.5 | X27: =20×0.5 → 10 m³/day | Y27: 70 | AA27: Strengths | AB27: 100% renewable and autonomous — powered by solar energy, no dependency on fuel or grid. | AC27: Weaknesses | AD27: High initial investment (~5,000–6,000 €).
A28: Drip irrigation | B28: m | C28: 2000 | D28: 0.25 | E28: =D28*C28 -> 500 | G28: Investment cost | H28: =E33 -> 5420 | I28: € | J28: Total CAPEX (equipment only) | M28: Post-Rainy (Transition) | N28: October – November | O28: 50–100 | P28: 2–3 | Q28: 10–12 | R28: 70–84 | S28: Light irrigation to maintain soil moisture | T28: FAO Irrigation Paper 56 | V28: Transition (Oct–Nov) | W28: 0.8 | X28: =20×0.8 → 16 m³/day | Y28: 112 | AB28: Reduces water consumption by up to 40% with smart drip and moisture sensors. | AD28: Requires technical knowledge for installation and maintenance.
A29: PV panels (400 Wp, JinkoSolar / Trina) | B29: unit | C29: 4 | D29: 105 | E29: =D29*C29 -> 420 | G29: Annual maintenance | H29: 50 | I29: €/year | J29: Estimated cost for cleaning filters, IoT subscription, small replacements | M29: Cool Dry (Early Dry) | N29: November – February | O29: 0–20 | P29: 3–4 | Q29: 12–15 | R29: 84–105 | S29: Moderate irrigation; tree recovery phase | T29: INERA Bobo-Dioulasso | V29: Cool Dry (Nov–Feb) | W29: 0.9 | X29: =20×0.9 → 18 m³/day | Y29: 126 | AB29: Low operating cost after installation. | AD29: Smart sensors and IoT systems may face connectivity issues in remote areas.
A30: Pump (1 kW DC solar pump) | B30: unit | C30: 1 | D30: 650 | E30: =D30*C30 -> 650 | G30: Payback period | H30: =H28/(H27-H29) -> 7.2266667 | I30: Years | J30: This is acceptable for rural solar investment. It means that the farmer will get the investment money back in 7.2 years | M30: Hot Dry (Peak Dry) | N30: March – April | O30: 0 | P30: 5–6 | Q30: 18–20 | R30: 126–140 | S30: Maximum irrigation demand period | T30: CILSS ClimData Burkina | V30: Hot Dry (Mar–Apr) | W30: 1 | X30: =20×1.0 → 20 m³/day | Y30: 140 | AB30: Adapted to local mango farms and scalable for larger farms. | AD30: Efficiency depends on sunlight availability (limited operation during cloudy days)
A31: Filtration + MPPT | B31: set | C31: 1 | D31: 250 | E31: =D31*C31 -> 250 | G31: Annuak net saving | H31: =H27-H29 -> 750 | I31: € | AB31: Long equipment lifespan (PV panels ≈ 25 years, pump ≈ 10 years) | AC31: Threats | AD31: Equipment theft or vandalism in rural areas.
A32: Smart add-ons | B32: set | C32: 1 | D32: 1800 | E32: =D32*C32 -> 1800 | G32: Project lifetime | H32: 25 | I32: years | AA32: Opportunities | AB32: Increasing demand for sustainable agriculture solutions in West Africa. | AD32: Fluctuations in market prices for imported equipment (PV panels, pumps).
A33: TOTAL | B33: _ | C33: _ | D33: _ | E33: =E27+E28+E29+E30+E31+E32 -> 5420 | G33: Pump replacement | H33: 650 | I33: € | M33: Water Needs by Growth Stage | S33: Irrigation strategy | AB33: Can be extended to other crops or community irrigation schemes. | AD33: Limited availability of spare parts and qualified technicians locally.
G34: MPPT/Controller replacement | H34: 250 | I34: € | M34: Tree Age | N34: Growth Stage | O34: Estimated Water Demand (L/day/tree) | P34: Irrigation Frequency | Q34: Comments | S34: Irrigation strategy | T34: Frequency | U34: Dose per tree per event (L) | V34: Total per event (m3) | W34: Pump runtime per event | X34: Pump runtime per day | Y34: Tank sufficiency | AB34: Possible subsidies or financing from green energy or agricultural development programs. | AD34: Climate variability may affect long-term water availability.
G35: Smart add-on replacement | H35: 1000 | I35: € | M35: 0–2 years | N35: Establishment | O35: 5–10 L | P35: Every 2–3 days | Q35: Frequent, low-volume irrigation for root development | S35: daily | T35: 1 | U35: =100*T35 -> 100 | V35: =(C22*U35)/1000 -> 20 | W35: =V35/F22 -> 5 | X35: =W35/T35 -> 5 | Y35: =30/D22 -> 1.5 | AB35: Opportunity to integrate with water recycling and AI-based scheduling for future upgrades.
A36: FINANCIAL ANALYSIS – WITH FORMULAS | G36: Total replacement cost | H36: =(H33*2)+(H34*2)+(H35*2) -> 3800 | I36: € | M36: 2–5 years | N36: Growth | O36: 20–50 L | P36: Every 3–5 days | Q36: Higher demand during canopy expansion | S36: every 2 days | T36: 2 | U36: =100*T36 -> 200 | V36: =(C22*U36)/1000 -> 40 | W36: =V36/F22 -> 10 | X36: =W36/T36 -> 5 | Y36: =30/D22 -> 1.5
A37: Parameter | B37: Value | C37: Unit | D37: Formula (Excel) | E37: Comment | G37: Total saving over 25 years of the project | H37: =H31*25 -> 18750 | I37: € | M37: 5–10 years | N37: Mature trees | O37: 80–120 L | P37: Every 5–7 days | Q37: Stable root system; main fruit-bearing stage | S37: every 5 days | T37: 5 | U37: =100*T37 -> 500 | V37: =(C22*U37)/1000 -> 100 | W37: =V37/F22 -> 25 | X37: =W37/T37 -> 5 | Y37: =30/D22 -> 1.5
A38: Daily energy consumption | B38: 2.2 | C38: kWh/day | D38: =0.44*5 | E38: Pₑ × irrigation time | G38: Total project cost | H38: =H28+H36 -> 9220 | I38: € | M38: >10 years | N38: Full production | O38: 100–150 L | P38: Every 5–7 days | Q38: Peak during fruit formation and dry season
A39: Annual energy (old calculation) | B39: 803 | C39: kWh/year | D39: =2.2*365 | E39: Theoric
A40: Reference annual energy (realistic) | B40: 469 | C40: kWh/year | D40: (Fixed value) | E40: Based on real use | N40: Total Farm Water Demand (From planting to dried mango production) | S40: Water Demand per Region
A41: Seasonal coefficient average fₛ | B41: 0.8 | C41: — | D41: =AVERAGE(0.5,0.8,0.9,1) | E41: Average of 4 seasons | G41: Updated Financial Analysis | N41: Stage | O41: Water Demand | P41: Formula | Q41: Result | S41: Region | T41: Rainfall (mm/year) | U41: ET₀ Level | V41: fₛ (coefficient) | W41: Daily Water Demand (m³/day) | X41: Weekly (m³/week) | Y41: Sources
A42: Seasonal energy consumption | B42: 281 | C42: kWh/year | D42: =469 * 0.8 | E42: Seasonal ajustement | G42: Parameter | H42: Value | I42: Unit | J42: Comment | N42: Orchard irrigation (annual) | O42: 20 m³/day × 245 dry days | P42: = 4900 m³/year | Q42: =20*245 -> 4900 | S42: Koubri (Centre) | T42: 700–900 | U42: Medium | V42: 1 | W42: 20 | X42: =W42*7 -> 140 | Y42: DG-Météo, FAO
A43: Annual water cost saved | B43: 800 | C43: €/year | D43: (Fixed value) | E43: Économie vs. manual/diesel | G43: Investment cost | H43: 5420 | I43: € | J43: Equipment only | N43: Washing mangoes | O43: 3 L/kg | P43: For 10 tons → 30 m³ | Q43: =3*10 -> 30 | S43: Bobo-Dioulasso (Hauts-Bassins) | T43: 1000–1200 | U43: Low | V43: 0.7 | W43: =V43*20 -> 14 | X43: =W43*7 -> 98 | Y43: ANAM, FAO ClimWat
A44: Annual energy saving | B44: 50 | C44: €/year | D44: =(469 - 281)*0.25 | E44: 0.25 €/kWh | G44: Maintenance | H44: 50 | I44: €/year | J44: Filters, IoT service | N44: Slicing & processing | O44: 1,5 L/kg | P44: = 15 m³ | Q44: =1.5*10 -> 15 | S44: Banfora (Cascades) | T44: 1100–1300 | U44: Low | V44: 0.6 | W44: =V44*20 -> 12 | X44: =W44*7 -> 84 | Y44: AGRHYMET
...

Sheet Processing Machines(Ange Marie)
A2: Financial and technical plan (12 months)
A3: Month | B3: Processed mangoes (kg) | | C3: Waste generated (kg) | D3: Biogas produced (m³) | E3: Dried mango produced (Kg) | F3: Compost produced | G3: Dried mango income (Euro) | H3: Compost income (Euro) | I3: Biogas income (Euro) | J3: Assumptions used | M3: Benefits of the project
A4: 1 | B4: =B24/12 -> 3666.6667 | C4: =B4*50% -> 1833.3333 | D4: =C4*50% -> 916.66667 | E4: =B4*50% -> 1833.3333 | F4: =C4*50% -> 916.66667 | G4: =E4*8 -> 14666.667 | H4: =F4*B33 -> 916.66667 | I4: =D4*B33 -> 916.66667 | J4: 1 kg of mango waste | K4: 0.043 | L4: m³ | M4: 1. Energy independence thanks to biogas
A5: 2 | B5: =B24/12 -> 3666.6667 | C5: =B5*50% -> 1833.3333 | D5: =C5*50% -> 916.66667 | E5: =B5*50% -> 1833.3333 | F5: =C5*50% -> 916.66667 | G5: =E5*8 -> 14666.667 | H5: =D5*B33 -> 916.66667 | I5: =D5*B33 -> 916.66667 | J5: 1 m³ of biogas | K5: 6 | L5: kWh | M5: 2. Waste conversion into compost and energy
A6: 3 | B6: =B24/12 -> 3666.6667 | C6: =B6*50% -> 1833.3333 | D6: =C6*50% -> 916.66667 | E6: =B6*50% -> 1833.3333 | F6: =C6*50% -> 916.66667 | G6: =E6*8 -> 14666.667 | H6: =F6*B33 -> 916.66667 | I6: =D6*B33 -> 916.66667 | J6: Fixed monthly cost | K6: 274.41 | M6: 3. Reduction in fossil fuel costs
A7: 4 | B7: =B24/12 -> 3666.6667 | C7: =B7*50% -> 1833.3333 | D7: =C7*50% -> 916.66667 | E7: =B7*50% -> 1833.3333 | F7: =C7*50% -> 916.66667 | G7: =E7*8 -> 14666.667 | H7: =F7*B33 -> 916.66667 | I7: =D7*B33 -> 916.66667 | J7: Selling price of dried mangoes | K7: 1 | L7: Euro/kg | M7: 4. Potential for carbon credits or green subsidies
A8: 5 | B8: =B24/12 -> 3666.6667 | C8: =B8*50% -> 1833.3333 | D8: =C8*50% -> 916.66667 | E8: =B8*50% -> 1833.3333 | F8: =C8*50% -> 916.66667 | G8: =E8*8 -> 14666.667 | H8: =F8*B33 -> 916.66667 | I8: =D8*B33 -> 916.66667 | J8: Compost selling price | K8: 0.5 | L8: Euro/kg | M8: 5. Creation of local jobs and strengthening of the agricultural value chain
A9: 6 | B9: =B24/12 -> 3666.6667 | C9: =B9*50% -> 1833.3333 | D9: =C9*50% -> 916.66667 | E9: =B9*50% -> 1833.3333 | F9: =C9*50% -> 916.66667 | G9: =E9*8 -> 14666.667 | H9: =F9*B33 -> 916.66667 | I9: =D9*B33 -> 916.66667 | J9: No additional energy costs thanks to biogas.
A10: 7 | B10: =B24/12 -> 3666.6667 | C10: =B10*50% -> 1833.3333 | D10: =C10*50% -> 916.66667 | E10: =B10*50% -> 1833.3333 | F10: =C10*50% -> 916.66667 | G10: =E10*8 -> 14666.667 | H10: =F10*B33 -> 916.66667 | I10: =D10*B33 -> 916.66667
A11: 8 | B11: =B24/12 -> 3666.6667 | C11: =B11*50% -> 1833.3333 | D11: =C11*50% -> 916.66667 | E11: =B11*50% -> 1833.3333 | F11: =C11*50% -> 916.66667 | G11: =E11*8 -> 14666.667 | H11: =F11*B33 -> 916.66667 | I11: =D11*B33 -> 916.66667
A12: 9 | B12: =B24/12 -> 3666.6667 | C12: =B12*50% -> 1833.3333 | D12: =C12*50% -> 916.66667 | E12: =B12*50% -> 1833.3333 | F12: =C12*50% -> 916.66667 | G12: =E12*8 -> 14666.667 | H12: =F12*B33 -> 916.66667 | I12: =D12*B33 -> 916.66667
A13: 10 | B13: =B24/12 -> 3666.6667 | C13: =B13*50% -> 1833.3333 | D13: =C13*50% -> 916.66667 | E13: =B13*50% -> 1833.3333 | F13: =C13*50% -> 916.66667 | G13: =E13*8 -> 14666.667 | H13: =F13*B33 -> 916.66667 | I13: =D13*B33 -> 916.66667
A14: 11 | B14: =B24/12 -> 3666.6667 | C14: =B14*50% -> 1833.3333 | D14: =C14*50% -> 916.66667 | E14: =B14*50% -> 1833.3333 | F14: =C14*50% -> 916.66667 | G14: =E14*8 -> 14666.667 | H14: =F14*B33 -> 916.66667 | I14: =D14*B33 -> 916.66667
A15: 12 | B15: =B24/12 -> 3666.6667 | C15: =B15*50% -> 1833.3333 | D15: =C15*50% -> 916.66667 | E15: =B15*50% -> 1833.3333 | F15: =C15*50% -> 916.66667 | G15: =E15*8 -> 14666.667 | H15: =F15*B33 -> 916.66667 | I15: =D15*B33 -> 916.66667
A17: Biogas production | E17: Features of the ball mill | I17: List of acronyms from the waste of biogas sheet
A18: Source of waste | B18: Quantity (kg/month) | C18: Biogas produced (m³/month) | D18: Compost produced (kg/month) | E18: Parameter | F18: Estimated value | G18: Unity | H18: Comments | I18: Acronyms | J18: Meaning
A19: Mango waste | B19: =B29*4 -> 611.11111 | C19: =D4 -> 916.66667 | D19: =F4 -> 916.66667 | E19: Type of shredder | F19: With cannonballs (small model) | G19: — | H19: Suitable for small-scale farming | I19: m³ | J19: Cubic meter
E20: Motor power | F20: 5 | G20: kW | H20: Electric motor and biogas | I20: kW | J20: Kilowatt
A21: 2-Hectare Mango Farm Weekly Financial Projection (EUR) | E21: Grinding capacity | F21: 300 | G21: kg/h | H21: Fresh or pre-treated mangoes | I21: kg/h | J21: Kilogram per hour
E22: Operating time | F22: 6 | G22: h/day | H22: Daily average | I22: h/day | J22: Hour per day
A23: Weekly Mango Input | B23: Quantity | C23: Unity | E23: Energy consumption | F23: 900 | G23: kWh/month | H23: Depending on use | I23: kWh | J23: Kilowatt hour
A24: Annual output | B24: 44000 | C24: Kg | E24: Biogas requirement | F24: 150 | G24: m³/month | H24: 1 m³ ≈ 6 kWh | I24: kg/month | J24: Kilogram per month
A25: Monthly output | B25: =B24/12 -> 3666.6667 | C25: Kg | I25: m³/month | J25: Cubic meter per month
A26: Weekly output | B26: =B25/12 -> 305.55556 | C26: Kg | E26: Main Machines and Equipment Needed for a Dried Mango Processing Unit | I26: kWh/month | J26: Kilowatt hour per month
A27: Dried mango | B27: =B26*50% -> 152.77778 | C27: Kg | E27: Type of machine | F27: Useful | G27: Cost per unit in euro | H27: Links | I27: kg | J27: Kilogram
A28: Mango powder | B28: =B27*50% -> 76.388889 | C28: Kg | E28: Dryer | F28: Used to dry the mango slices after preparation. | G28: 4,162.25 | H28: https://www.alibaba.com/product-detail/NP-Brand-Food-Dehydrators-for-Sale_1601274819369.html?spm=a2706.7843667.0.0.7f6a549481sKM5
A29: Waste (peels + seeds) | B29: =B26*50% -> 152.77778 | C29: Kg | E29: Mango Slicer | F29: Cuts mangoes into uniform slices before drying. | G29: 17,302.53 | H29: https://m.made-in-china.com/product/Lonkia-Turbo-Commercial-Mango-Peeler-High-Speed-Deskinning-2103944972.html?utm_source=chatgpt.com
A30: Weekly Revenue (EUR) | B30: Unit Price (€) | C30: Total Price | E30: Washing and Peeling Station | F30: For cleaning mangoes and optionally peeling them.
A31: Dried mango | B31: 8 | C31: =B31*B27 -> 1222.2222 | E31: Electronic Scale | F31: To weigh fresh mangoes, sliced mangoes, and the final dried product to control yield. | G31: 1,090.06 | H31: Electronic Scales Full Electric Pallet Truck 3ton 3t Factory Price - Pallet Jack and Electric Pallet Truck
A32: Mango powder | B32: 13 | C32: =B32*B28 -> 993.05556 | E32: Stainless-Steel Preparation Tables | F32: Used during sorting, cutting, and arranging slices on trays. | G32: 181.67 | H32: 30" x 72" Stainless Steel Commercial Work Table
A33: Waste (peels + seeds) | B33: 1 | C33: =B33*B29 -> 152.77778 | E33: Drying Trays | F33: Where the mango slices are placed during drying. | G33: 5.85 | H33: Plateau de rangement en acier inoxydable, plateau de stockage, plaque de fuite, trou, passoire à mailles, lavage des légumes, séchage du bassin, filtre à eau, couvercle du bassin, 304 - AliExpress 15
A34: Total weekly revenue | B34: =B31+B32+B33 -> 22 | C34: =C31+C32+C33 -> 2368.0556 | E34: Thermometer and Hygrometer | F34: To monitor temperature and humidity during the drying process. | G34: 9.7 | H34: TFA Thermo-Hygrometer Comfort – Thomann France
A35: Weekly Costs (EUR) | B35: Quantity | C35: Unit Price (€) | D35: Total Price | E35: Plastic Bins | F35: For storing mangoes before and after drying. | G35: 2.77 | H35: Warehouse Industrial Plastic Stackable Storage Bins for Spare Parts Manufacturers & Suppliers – Made-in-China.com
A36: Raw mango | B36: =B26 -> 305.55556 | C36: 2 | D36: =B36*C36 -> 611.11111 | E36: Heat Sealing / Packaging Machine | F36: To seal dried mangoes in airtight packaging. | G36: 4,481.36 | H36: Machine À Emballer Automatique De Grains Robuste De 25kg Avec Système De Thermoscellage À Coudre Pour L'emballage De Boîtes De Sacs En Carton - Buy Paper Wrapping Machine glass Packaging Machine easy To Operate Packaging Machine chemical Packing Machine gearbox Sealing System automatic Grain Packaging carton Bag Packaging film Packaging Machine fully Automatic Packaging pet Packing Material pp Packaging Material Product on Alibaba.com
A37: Workers | B37: 2 | C37: 50 | D37: =B37*C37 -> 100 | E37: Refractometer | F37: To check sugar content and support quality control. | G37: 59 | H37: Réfractomètre de vigneron AT 32 | Brix Meter 0–32% | Réfractomètre de bière | avec ATC pour le brassage de la bière pour mesurer la teneur en sucre pour la production de vins de qualité : Amazon.fr: Cuisine et Maison
A38: Energy and maintenance | B38: 1 | C38: 46 | D38: =B38*C38 -> 46
A39: Packaging | B39: =B27+B28 -> 229.16667 | C39: 1 | D39: =B39*C39 -> 229.16667
A40: Total weekly cost | B40: =B36+B37+B38+B39 -> 537.72222 | C40: =C36+C37+C38+C39 -> 99 | D40: =D36+D37+D39+D38 -> 986.27778
A41: Weekly Profit & Margin
A42: Profit per week | B42: =C34-D40 -> 1381.7778
...

Sheet Smart Dryer(Cedric)
A1: Smart dryer financial planning (10 Years)
A7: 2ha Summary table
A8: CAPEX or Total One-Time Cost (EUR) | C8: OPEX or Total Recurring Cost per year (EUR) | E8: Revenue & Profitability
A9: Processing machines (full chain) | B9: =SUM(B43:B48) -> 8861 | C9: Production cost (2 ha × €3/kg dried × 1600 kg) | D9: =G108 -> 4800 | E9: Annual dried output | F9: 1 600 kg
A10: Dryers (2 units) | B10: =B29*2 -> 5302 | C10: Energy | D10: =I108 -> 137 | E10: Export price | F10: 30 €/kg
A11: IoT sensors (per dryer ×2) | B11: {=Tableau6[sensor_cost_per_dryer_€]*2} -> 152 | C11: Maintenance | D11: 46 | E11: Yearly Revenue | F11: 48000
A12: IoT Installation | B12: {=Tableau6[installation_cost_per_dryer_€]*2} -> 60 | C12: Connectivity | D12: 48 | E12: Net Profit (yearly) | F12: =F11-D14 -> 42787
A13: IoT Gateway | B13: 227 | C13: Cloud subscription | D13: 182 | E13: ROI Calculation (first year) | F13: 2.93
A14: Total CAPEX | B14: =SUM(B9:B13) -> 14602 | C14: Total OPEX | D14: =SUM(D9:D13) -> 5213 | E14: Long-term ROI (annual) | F14: 8.21
A19: Parameters (final output)
A20: Parameter | B20: Value | C20: Unit / Note
A21: Yield per ha | B21: 10000 | C21: kg/ha/an
A22: Recovery rate | B22: 0.8 | C22: Rate (80%)
A23: Transformation ratio (fresh to dry) | B23: 4 | C23: kg fresh -> 0,4 kg dried
A24: Cost of a fresh mango | B24: 0.5 | C24: €/kg
A25: Export price (dried) | B25: 30 | C25: €/kg dried
A26: Capacity per cycle (dryer) | B26: 500 | C26: kg fresh/cycle
A27: Campaign duration | B27: 120 | C27: days (4 months)
A28: Max cycles per dryer (4 months) | B28: 32 | C28: cycles
A29: Unit cost per dryer | B29: 2651 | C29: €
A30: Unit cost (2ha) | B30: 3 | C30: €/kg dried
A36: IOT
A37: add_fan_power_kW | B37: sensor_cost_per_dryer_€ | C37: gateway_cost_per_site_€ | D37: connectivity_monthly_per_dryer_€ | E37: cloud_subscription_annual_€ | F37: installation_cost_per_dryer_€ | G37: iot_capex_lifetime_years
A38: 1.5 | B38: 76 | C38: 227 | D38: 2 | E38: 182 | F38: 30 | G38: 5
A42: Machine | B42: Price (€)
A43: Elevators | B43: 909
A44: Bubble washer | B44: 1060
A45: Sorter | B45: 2271
A46: Cleaner | B46: 758
A47: Dryer | B47: 2651
A48: Peeler | B48: 1212
A49: Total | B49: =SUM(B43:B48) -> 8861
A54: EMPLOYMENT
A56: Variables | B56: Modalities | C56: Frequencies (%)
A57: - | B57: - | C57: Drying units | D57: Producers
A58: Sex | B58: Man | C58: 91.67 | D58: 100
B59: Women | C59: 8.33 | D59: 0
A60: Age | B60: ] 20 ; 29[ | C60: 10.83 | D60: -
B61: ] 30 ; 39[ | C61: 8, 33 | D61: -
B62: ] 40 ; 49[ | C62: 53.61 | D62: -
...

Sheet Solar PV power plant(Abdoul)
B2: TECHNICAL DEFINITIONS | E2: Irrigation & Miscellaneous Loads | I2: ENERGY CONSUMPTION (kWh/day)
B3: Term / Abbreviation | C3: Definition | E3: Parameter | F3: Value | G3: Source | I3: Scenario | J3: Pump | K3: Misc. loads | L3: Dryer | M3: TOTAL (kWh/day)
B4: ha | C4: Hectare (10,000 m²) | E4: Pump power | F4: 1.5 kW | G4: 1.5 HP Pump | I4: Base | J4: 6 | K4: 15 | L4: 0 | M4: 21
B5: PSH | C5: Peak Sun Hours: equivalent full-power sunlight hours | E5: Pump operating time | F5: 4 h | G5: Agricultural estimate | I5: 50 kg/day | J5: 6 | K5: 15 | L5: 150 | M5: 171
B6: Derate Factor | C6: Overall PV system losses (heat, dust, cables) | E6: Miscellaneous loads | F6: 3 kW | G6: Various equipment | I6: 200 kg/day | J6: 6 | K6: 15 | L6: 600 | M6: 621
B7: P_h [kW] | C7: Hydraulic power required by the pump | E7: Miscellaneous load duration | F7: 5 h | G7: Standard farm | I7: 1,000 kg/day | J7: 6 | K7: 15 | L7: 3000 | M7: 3021
B8: P_e [kW] | C8: Electrical power required by the pump
B9: PV [kWp] | C9: Peak power of the photovoltaic system | E9: Mango Drying
B10: MPPT | C10: Maximum Power Point Tracking – PV efficiency optimization | E10: Parameter | F10: Value
B11: Smart add-ons | C11: Sensors, IoT, PLCs, GSM/Wi-Fi monitoring | E11: Energy efficiency of drying | F11: 3 kWh/kg of fresh mango
B12: DoD | C12: Depth of Discharge – battery discharge depth | E12: Production Scenario 1 | F12: 50 kg/day
B13: BOS | C13: Balance of System – structure, cables, protections | E13: Production Scenario 2 | F13: 200 kg/day
B14: LCOE | C14: Levelized Cost of Energy – real energy cost | E14: Production Scenario 3 | F14: 1,000 kg/day
B16: Solar Parameters | F16: Battery Parameters
B17: Parameter | C17: Value | D17: Notes | F17: Parameter | G17: Value
B18: PSH Burkina Faso | C18: 5.5 h | F18: Battery type | G18: Lithium-ion
B19: Tracker gain | C19: 0.2 | F19: DoD | G19: 0.8
B20: Effective PSH | C20: 6.6 h | F20: Inverter efficiency | G20: 0.9
B21: Loss factor | C21: 0.25 | F21: Desired autonomy | G21: 8 h
B22: Derate factor | C22: 0.75
B23: Average area per kWp | C23: 8.5 m² | D23: Trackers
B25: Complete PV System
B26: Item | C26: Value | E26: Scenario | F26: Energy (kWh/day) | G26: PV required (kWp) | H26: No. of 400W panels | I26: Area m² | J26: Area ha
B27: Required PV = Energy / (PSH × Derate) | C27: PV = kWh / 4.95 | E27: Base | F27: 21 | G27: 4.24 | H27: 11 | I27: 36 | J27: 0.004
E28: 50 kg/day | F28: 171 | G28: 34.55 | H28: 87 | I28: 294 | J28: 0.029
E29: 200 kg/day | F29: 621 | G29: 125.45 | H29: 314 | I29: 1066 | J29: 0.107
E30: 1,000 kg/day | F30: 3021 | G30: 610.3 | H30: 1526 | I30: 5188 | J30: 0.519
B33: BATTERY SIZING
B34: Parameter | C34: Formula | E34: Scenario | F34: Energy / 8h (kWh) | G34: With losses (kWh) | H34: Nominal capacity (kWh)
B35: Energy 8h = (kWh/day ÷ 24) × 8 | C35: Usable energy | E35: Base | F35: 7 | G35: 7.78 | H35: 9.72
B36: Energy with losses = usable ÷ 0.9 | C36: Actual required energy | E36: 50 kg/day | F36: 57 | G36: 63.33 | H36: 79.17
B37: Total capacity = actual ÷ DoD | C37: Final battery capacity (kWh) | E37: 200 kg/day | F37: 207 | G37: 230 | H37: 287.5
E38: 1,000 kg/day | F38: 1007 | G38: 1118.89 | H38: 1398.61
B40: COSTS (CAPEX)
B41: Component | C41: Price | E41: Scenario | F41: PV cost ($) | G41: Battery ($) | H41: Inverter ($) | I41: Total CAPEX ($)
B42: PV + BOS | C42: $1.20/W | E42: Base | F42: 5088 | G42: 3888 | H42: 4500 | I42: 13476
B43: Li-Ion Battery | C43: $400/kWh | E43: 50 kg/day | F43: 41460 | G43: 31668 | H43: 30000 | I43: 103128
B44: Inverter | C44: $1,000/kW | E44: 200 kg/day | F44: 150540 | G44: 115000 | H44: 110000 | I44: 375540
E45: 1,000 kg/day | F45: 732360 | G45: 559444 | H45: 540000 | I45: 1831804
B48: ROI (Return on Investment)
...

Sheet Solar tracking(Narcisse)
F4: Scenario | G4: Daily Energy (kWh/day) | H4: Required PV Array (kWp) | I4: Number of 400 W Panels | J4: Required Battery (usable kWh) | K4: Inverter Size (kW, nominal)
F5: Small farm (≈2 ha) | G5: 37 | H5: 7.5 | I5: 19 | J5: 52 | K5: 6.3
G7: TABLEAU 1: Farm Scenario
F8: Parameter | G8: Metric | H8: Value | I8: Comment
F9: Scenario | G9: Description | H9: Small farm (≈2 ha) | I9: Fixed base
F10: Daily Energy | G10: kWh/day | H10: 37 | I10: Total daily consumption
F11: Required PV Array | G11: kWp | H11: 7.5 | I11: Fixed-tilt system
F12: Required PV Array | G12: kWp | H12: 6 | I12: With tracking
F13: 400 W Panels | G13: Units | H13: 19 | I13: Fixed-tilt
F14: 400 W Panels | G14: Units | H14: 15 | I14: Tracking
F15: Battery | G15: Usable kWh | H15: 52 | I15: Storage requirement
F16: Inverter Size | G16: kW | H16: 6.3 | I16: Nominal rating
G19: TABLEAU 2 : Calculation Summary
F21: Parameter | G21: Metric | H21: Value | I21: Comment
F22: Daily Energy | G22: kWh/day | H22: 37 | I22: Same for both systems
F23: PV Power (Fixed-Tilt) | G23: kWp | H23: 7.6 | I23: Baseline
F24: PV Power (Tracking) | G24: kWp | H24: 6 | I24: 20% reduction
F25: Panels (Fixed-Tilt) | G25: Units | H25: 19 | I25: 0.4 kW each
F26: Panels (Tracking) | G26: Units | H26: 15 | I26: 0.4 KW each
F27: System Cost (Fixed-Tilt) | G27: € | H27: 43825 | I27: Total system cost
F28: System Cost (Tracking) | G28: € | H28: 42850 | I28: Lower due to fewer panels
F29: Payback Period (Fixed-Tilt) | G29: Years | H29: 32 | I29: =Cost/Savings
F30: Payback Period (Tracking) | G30: Years | H30: 31 | I30: =Cost/Savings
F31: Annual Savings | G31: €/year | H31: 1351 | I31: =Annual production×rate
G34: TABLEAU 3: Energy Breakdown (37 kWh/day)
F36: Parameter | G36: Metric | H36: Value | I36: Comment
F37: Irrigation | G37: kWh/day | H37: 17 | I37: Efficient pumps
F38: Ventilation/Greenhouses | G38: kWh/day | H38: 7 | I38: Climate control
F39: Storage/Cooling | G39: kWh/day | H39: 5 | I39: Refrigeration
F40: Tools/Machinery | G40: kWh/day | H40: 4 | I40: Farm tools
F41: Electric Fences | G41: kWh/day | H41: 2 | I41: Protection system
F42: Office/Management | G42: kWh/day | H42: 2 | I42: Monitoring
F43: Total | G43: kWh/day | H43: =SUM(H37:H42) -> 37 | I43: Optimized consumption
G45: TABLEAU 4 :System Size and Explanation
F47: Parameter | G47: Metric | H47: Value | I47: Comment
F48: PV Size (Fixed-Tilt) | G48: kWp | H48: =PRODUCT(H13,0.4) -> 7.6 | I48: 19 panels × 0.4 kW
F49: PV Size (Tracking) | G49: kWp | H49: =PRODUCT(H26,0.4) -> 6 | I49: 15 panels × 0.4 kW
F50: Tracking Gain | G50: % | H50: 30 | I50: Higher solar yield
F51: Panel Reduction | G51: % | H51: -20 | I51: Fewer panels needed
G53: TABLEAU 5 : Cost Breakdown
...

Sheet Narcisse
A1: Design of an Energy-Efficient Warehouse for Preserving Dried Mangoes Until Distribution
A3: Zone | B3: Purpose | C3: Length (m) | D3: Width (m) | E3: Area (m²) | F3: Target Temp (°C) | G3: Target RH (%) | H3: Equipment | I3: Energy-efficient tech | J3: Estimated CAPEX (€) | K3: Estimated OPEX/year (€) | L3: Approx. Cooling Load (kW)
A4: Receiving & Inspection | B4: Unloading trucks, quality check, initial sorting | C4: 8 | D4: 6 | E4: 48 | F4: 20 to 25 | G4: 40-60 | H4: Unloading table, scales, pallets | I4: LED lighting, motion sensors, natural daylighting | J4: 3000 | K4: 500 | L4: 1.5
A5: Conditioning / Re-drying | B5: Optional re-drying or moisture equilibration | C5: 6 | D5: 5 | E5: 30 | F5: 40 to 60 (process) | G5: 10-20 (process) | H5: Hot air oven, hygrometer | I5: Heat-recovery ventilator, insulated chamber, PID control | J5: 5000 | K5: 1000 | L5: 6 (process heating)
A6: Bulk Dry Storage (racked) | B6: Main storage for dried mango in bulk or boxes | C6: 20 | D6: 12 | E6: 240 | F6: 15 to 20 | G6: 50-55 | H6: Racks, fans, dehumidifier | I6: Insulated envelope, dehumidifier with hygrostats, HVAC with heat recovery, LED | J6: 10000 | K6: 1500 | L6: 8
A7: Packaging & Sealing | B7: Weighing, packaging, vacuum/MAP sealing, labeling | C7: 7 | D7: 5 | E7: 35 | F7: 18 to 22 | G7: 50-60 | H7: Tables, scales, MAP sealer, labeler | I7: Efficient packers, LED, schedule-based ventilation | J7: 6000 | K7: 1000 | L7: 2
A8: Cold Holding (optional) | B8: Short-term holding for packaged product before shipment | C8: 5 | D8: 4 | E8: 20 | F8: 10 to 15 | G8: 30-50 | H8: Cold room, mobile racks | I8: High-efficiency compressor, door curtains, variable-speed drives | J8: 8000 | K8: 1200 | L8: 5
A9: Loading & Dispatch | B9: Staging for outbound shipments | C9: 8 | D9: 6 | E9: 48 | F9: 20 to 25 | G9: 40-60 | H9: Pallets, pallet jacks | I9: LED lighting, insulated loading doors | J9: 2000 | K9: 400 | L9: 1
A10: Utilities & Mechanical | B10: House HVAC, dehumidifiers, solar inverter, backup generator | C10: 4 | D10: 3 | E10: 12 | F10: N/A | G10: N/A | H10: Central HVAC, dehumidifier, inverter, generator | I10: Solar PV + battery, energy monitoring, VFD on fans | J10: 12000 | K10: 2000 | L10: N/A
A11: Office & QC Lab | B11: Admin, quality control testing, record keeping | C11: 6 | D11: 4 | E11: 24 | F11: 20 to 24 | G11: 40-60 | H11: Desks, PCs, microscopes, scales | I11: Efficient appliances, daylighting, timers | J11: 5000 | K11: 800 | L11: 0.5
A14: Glossary / Abbreviations:
A15: CAPEX = Capital Expenditure (investment in equipment & infrastructure) | B15: Estimated Totals:
A16: OPEX = Operational Expenditure (annual operating costs) | B16: Total CAPEX ≈ €51,000
A17: MAP = Modified Atmosphere Packaging (technique to preserve food) | B17: Total annual OPEX ≈ €8,400
A18: kW = Kilowatt (unit of power / cooling load)
A19: N/A = Not Applicable
A20: QC Lab = Quality Control Laboratory
A21: HVAC = Heating, Ventilation, and Air Conditioning
A22: RH = Relative Humidity (humidity % to maintain product quality)
B27: Analysis and Justification of Technical Choices: The facility layout and design parameters were defined according to the specific thermal and operational needs of each zone. Temperature and humidity targets are carefully adjusted to maintain mango quality during receiving, conditioning, drying, storage, and packaging operations. Energy-efficient technologies such as LED lighting, motion sensors, heat-recovery ventilation, insulated envelopes, and variable-speed drives have been selected to minimize energy losses and optimize indoor environmental conditions. The integration of dehumidifiers with hygrostats and automated HVAC control ensures stable storage conditions, while MAP sealers and cold rooms preserve product integrity before dispatch. In the utilities section, the inclusion of a solar photovoltaic system with battery storage and energy monitoring reduces grid dependency and lowers operational costs (OPEX). Overall, these technical decisions reflect a sustainable and cost-effective approach, combining energy efficiency, process reliability, and environmental responsibility.

Sheet No Reesa(Afiatou)
B1: No-Reesa (voice translation app)
A4: Importance of Moore → German Voice Translation in the Dried Mango Trade
A6: Indicator | B6: Without Voice Translation App (per year) | C6: With Voice Translation App (per year) | D6: Gain due to No-Reesa App | E6: Impact (%)
A7: Number of international buyers reached | B7: 80 | C7: 160 | D7: 80 | E7: 1
A8: Total sales (million XOF) | B8: 8.5 | C8: 15.2 | D8: +6.7 | E8: 78.8%
A9: Amount spent on interpreters (million XOF) | B9: 2.1 | C9: 0 | D9: +2.1 | E9: 1
A10: Export success rate | B10: 0.55 | C10: 0.85 | D10: 0.3 | E10: 54.5%
A11: Customer satisfaction rate | B11: 0.6 | C11: 0.92 | D11: 0.32 | E11: 53.3%
A12: Average delivery agreements per month | B12: 5 | C12: 9 | D12: 4 | E12: 0.8
B14: Investment Needed
A16: Category | B16: Description | C16: Estimated Cost (EUR)
A17: App Development | B17: Simplified extension with limited language pairs & interface reuse | C17: 1.832
A18: Data Collection & Translation | B18: Small dataset (≈5,000 sentences) using local contributors | C18: 1.374 | H18: Bibliography
A19: AI Model Training | B19: Training using pre-trained multilingual models (less compute cost) | C19: 916
A20: Testing & Quality Assurance | B20: Basic linguistic and user testing | C20: 458 | G20: Source | H20: Description | I20: Link
A21: Marketing & Promotion | B21: Digital marketing and awareness in target communities | C21: 611 | G21: Upwork (2024) | H21: Developer cost estimates for mobile app projects in Africa | I21: https://www.upwork.com
A22: Infrastructure & Hosting | B22: Basic cloud instance and database | C22: 458 | G22: AI4D Africa (2023) | H22: Language data collection cost reference | I22: https://ai4d.ai
A23: Team Salaries (3 months) | B23: Small core team (1 dev, 1 linguist, 1 PM) | C23: 1.832 | G23: Hugging Face (2024) | H23: AI model training and hosting benchmarks | I23: https://huggingface.co
A24: Legal & Administrative Fees | B24: Simplified registration & documentation | C24: 229 | G24: Google Cloud (2024) | H24: Cloud storage and hosting pricing | I24: https://cloud.google.com
A25: Contingency (10%) | B25: Buffer for adjustments | C25: 763 | G25: API-BF (2024) | H25: Administrative and registration costs in Burkina Faso | I25: https://www.apibf.bf
A26: Total Estimated Investment | C26: 8.473

Sheet Face Recognition(Yanick)
A1: PROJECT FINANCIAL SUMMARY
A3: Metric | B3: Result | C3: Explanation
A4: Total Investment | B4: =SUM(E29:E30) -> 11770 | C4: The total cost of the security system including installation.
A5: Annual Savings | B5: =SUM(B45:B47) -> 27400 | C5: The total amount saved per year from theft reduction, personnel cost reduction, and efficiency gains.
A6: Payback Period | B6: =B53/B54 -> 0.42956204 | C6: The time it takes for the annual savings to cover the initial investment.
A7: Annual ROI | B7: =B54/B53 -> 2.3279524 | C7: The annual return on investment, indicating high profitability.
A10: GENERAL INFORMATION
A12: Item | B12: Details
A13: Project Name | B13: Mango Drying Farm Security System
A14: Farm Location | B14: Location Of The Farm
A15: Farm Area | B15: 2 Hectares
A16: Objectives | B16: Theft reduction, improved monitoring
A17: Crop | B17: Mango
A18: Currency | B18: Euro (€)
A20: COMPONENTS AND COSTS
A22: Component | B22: Unit | C22: Quantity | D22: Unit Cost (€) | E22: Subtotal (€) | F22: Specifications
A23: Perimeter fence | B23: meter | C23: 9 | D23: 600 | E23: =Tableau11[[#This Row],[Quantity]]*Tableau11[[#This Row],[Unit Cost (€)]] -> 5400 | F23: Security fence
A24: Perimeter cameras | B24: unit | C24: 12 | D24: 140 | E24: =Tableau11[[#This Row],[Quantity]]*Tableau11[[#This Row],[Unit Cost (€)]] -> 1680 | F24: 4MP, weatherproof
A25: Face recognition cameras | B25: unit | C25: 2 | D25: 190 | E25: =Tableau11[[#This Row],[Quantity]]*Tableau11[[#This Row],[Unit Cost (€)]] -> 380 | F25: AI technology
A26: Internal cameras | B26: unit | C26: 8 | D26: 110 | E26: =Tableau11[[#This Row],[Quantity]]*Tableau11[[#This Row],[Unit Cost (€)]] -> 880 | F26: Indoor monitoring
A27: Monitoring system | B27: unit | C27: 1 | D27: 1400 | E27: =Tableau11[[#This Row],[Quantity]]*Tableau11[[#This Row],[Unit Cost (€)]] -> 1400 | F27: Server + software
A28: Access control | B28: unit | C28: 2 | D28: 480 | E28: =Tableau11[[#This Row],[Quantity]]*Tableau11[[#This Row],[Unit Cost (€)]] -> 960 | F28: Entry control
A29: SUB-TOTAL | E29: =SUM(E23:E28) -> 10700 | F29: SUB-TOTAL
A30: Installation | E30: =SUM(E23:E28)*10/100 -> 1070 | F30: 10% of equipment
A31: TOTAL INVESTMENT | E31: =SUM(E29:E30) -> 11770 | F31: TOTAL INVESTMENT
A33: ASSUMPTIONS & BASE VALUES
A35: Description | B35: Value
A36: Previous annual losses | B36: 10000
A37: Security guard annual salary | B37: 20000
A38: Annual maintenance costs | B38: 36000
A39: Theft reduction rate | B39: 0.2
A40: Maintenance improvement rate | B40: 0.15
A42: ANNUAL BENEFITS
A44: Benefit Type | B44: Amount (€) | C44: Details
A45: Theft reduction | B45: =B36*B39 -> 2000 | C45: Loss prevention
A46: Personnel cost reduction | B46: =B37 -> 20000 | C46: Automated monitoring
A47: Maintenance improvement | B47: =B38*B40 -> 5400 | C47: Efficiency gains
A48: TOTAL SAVINGS | B48: =SUM(B45:B47) -> 27400 | C48: TOTAL SAVINGS
A50: FINANCIAL ANALYSIS
A52: Indicator | B52: Value | C52: Formula
...
