Workbook

Sheet Sources & Methodology
A1: Energy Supply Systems — Sources & Methodology
A2: Infineon/BIT Excellence Program 2026 — Module 05 — corrections and data sources for the Base scenario
A4: Parameter | B4: Value | C4: Unit | D4: Source | E4: Reference Year | F4: Notes
A5: Peak Sun Hours (PSH) | B5: 5.5 | C5: kWh/m²/day | D5: Nana, Zallé, Ouarma, Daho, Yonli & Béré (2023), "Assessment of carbon dioxide emission factors from power generation in Burkina Faso", Clean Air Journal 33(2), citing MEEVCC (2018) | E5: 2018 | F5: Burkina Faso national average. Regional range 3.0-7.5 kWh/m²/day depending on climatic zone (38-year climate dataset, 6 weather stations, published 2012). Ouagadougou-area sites are typically at or above the national average.
A6: Performance Ratio (system derating) | B6: 0.75 | C6: ratio (0-1) | D6: Team assumption, standard for off-grid Sahel PV systems | E6: 2026 | F6: Accounts for real-world losses: dust/soiling, temperature derating, inverter and wiring losses. Adjustable between 0.70-0.80; 0.75 used as a conservative mid-point.
A7: Grid Emission Factor (SONABEL) | B7: 0.569 | C7: kg CO2/kWh | D7: Nana, Zallé, Ouarma, Daho, Yonli & Béré (2023), Clean Air Journal 33(2) | E7: 2018 | F7: Reflects the 2018 national electricity mix (14.25% renewables). Likely a conservative (high) estimate for 2026, since solar capacity on the SONABEL grid (e.g. Zagtouli, Nagreongo, Zina) has increased since 2018.
A8: PV Lifecycle Emission Factor | B8: 0.048 | C8: kg CO2/kWh | D8: IPCC (2014), Fifth Assessment Report, Working Group III, Annex III: Technology-specific Cost and Performance Parameters | E8: 2014 | F8: Median value for utility-scale solar PV (published range: 18-180 g CO2eq/kWh across reviewed studies). Used to net out PV's own manufacturing/lifecycle footprint from gross CO2 avoided.
A9: Panel unit price | B9: 1200 | C9: €/kWp | D9: Project Excel file, 2025 cohort (Abdoul's Solar PV Power Plant sheet) | E9: 2025 | F9: KEPT UNCHANGED per team decision — not re-verified against current market prices. For reference, this is broadly consistent with retail monocrystalline panel prices observed in the West African FCFA zone as of Sep 2026 (~680-690 FCFA/Wc).
A10: Battery unit price | B10: 400 | C10: €/kWh | D10: Project Excel file, 2025 cohort | E10: 2025 | F10: KEPT UNCHANGED per team decision — not re-verified against current market prices. For reference, regional lithium battery retail prices observed as of Sep 2026 ranged roughly 60,000-105,000 FCFA/kWh, below this figure — worth revisiting if the team wants an up-to-date CAPEX estimate later.
A12: Legend
A13: Blue text = hardcoded input/assumption
A14: Black text = source/documentation text

Sheet Base Scenario - PV & CO2
A1: Base Scenario — PV Sizing and CO2 Avoided (corrected)
A2: Resolves the two pending TODO values in EnergySupplyDataSeeder.java (PV capacity, CO2 avoided)
A4: A. Daily Load Breakdown — Base Scenario
A5: Load Category | B5: kWh/day
A6: Irrigation pump | B6: 7.5
A7: Miscellaneous (2025 baseline, Abdoul) | B7: 15
A8: Storage / Cooling | B8: 8
A9: Lighting | B9: 2
A10: Security (fencing & cameras) | B10: 1
A11: Monitoring / IoT | B11: 0.5
A12: Total Daily Load | B12: =SUM(B6:B11) -> 34
A14: B. PV Capacity Sizing
A15: Total Daily Load | B15: =B12 -> 34 | C15: kWh/day
A16: Peak Sun Hours (PSH) | B16: ='Sources & Methodology'!B5 -> 5.5 | C16: kWh/m²/day | D16: Linked from Sources & Methodology sheet.
A17: Performance Ratio | B17: ='Sources & Methodology'!B6 -> 0.75 | C17: ratio | D17: Linked from Sources & Methodology sheet.
A18: Required PV Capacity | B18: =B15/(B16*B17) -> 8.2424242 | C18: kWp | D18: Formula: Daily Load / (PSH x Performance Ratio)
A19: Panel unit price | B19: ='Sources & Methodology'!B9 -> 1200 | C19: €/kWp | D19: Linked from Sources & Methodology sheet — kept unchanged from the original 2025 file.
A20: PV CAPEX (panels only) | B20: =B18*B19 -> 9890.9091 | C20: € | D20: Formula: PV Capacity x Panel unit price
A22: B2. Battery Capacity Sizing
A23: Total Daily Load | B23: =B12 -> 34 | C23: kWh/day
A24: Depth of Discharge (DoD) | B24: 0.8 | C24: ratio (0-1) | D24: Standard assumption for LiFePO4 batteries, to preserve battery lifespan.
A25: Autonomy (days) | B25: 1 | C25: days | D25: DESIGN ASSUMPTION, not externally sourced like PSH/grid factor above — confirm with team. 1 day chosen for cost reasons (matches the team's CAPEX-conscious approach after the fixed-scenario model was rejected for its 31-32 year payback).
A26: Required Battery Capacity | B26: =(B23*B25)/B24 -> 42.5 | C26: kWh | D26: Formula: (Daily Load x Autonomy days) / Depth of Discharge
A27: Battery unit price | B27: ='Sources & Methodology'!B10 -> 400 | C27: €/kWh | D27: Linked from Sources & Methodology sheet — kept unchanged from the original 2025 file.
A28: Battery CAPEX | B28: =B26*B27 -> 17000 | C28: € | D28: Formula: Battery Capacity x Battery unit price
A30: C. CO2 Avoided (Annual, Base Scenario)
A31: Total Daily Load | B31: =B12 -> 34 | C31: kWh/day
A32: Annual Energy Production | B32: =B31*365 -> 12410 | C32: kWh/year
A33: Grid Emission Factor (SONABEL) | B33: ='Sources & Methodology'!B7 -> 0.569 | C33: kg CO2/kWh | D33: Linked from Sources & Methodology sheet.
A34: Gross CO2 Avoided vs Grid | B34: =B32*B33 -> 7061.29 | C34: kg CO2/year | D34: Formula: Annual production x Grid emission factor
A35: PV Lifecycle Emission Factor | B35: ='Sources & Methodology'!B8 -> 0.048 | C35: kg CO2/kWh | D35: Linked from Sources & Methodology sheet.
A36: PV Lifecycle Emissions | B36: =B32*B35 -> 595.68 | C36: kg CO2/year | D36: Formula: Annual production x PV lifecycle emission factor
A37: Net CO2 Avoided (Annual) | B37: =B34-B36 -> 6465.61 | C37: kg CO2/year | D37: Formula: Gross CO2 avoided - PV lifecycle emissions.
A38: Net CO2 Avoided (Monthly) | B38: =B37/12 -> 538.80083 | C38: kg CO2/month | D38: Formula: Annual net CO2 avoided / 12. USE THIS VALUE for EnergySupplyDataSeeder.java's CarbonMetric.co2AvoidedKg, since that entity's `period` field is the first day of the current month (a monthly figure, not annual).
A40: D. Seeder Values Summary (for EnergySupplyDataSeeder.java)
A41: Field | B41: Old placeholder | C41: Corrected value
A42: pv.setCapacityValue (kWp) | B42: 10.5 | C42: =B18 -> 8.2424242
A43: battery.setCapacityValue (kWh) | B43: 20.0 | C43: =B26 -> 42.5
A44: metric.setCo2AvoidedKg (kg/month) | B44: 420.00 | C44: =B37/12 -> 538.80083
A45: metric.setEmissionFactorUsed | B45: 0.500 | C45: =B33 -> 0.569
...

Sheet Panel & Battery Pricing
A1: Panel & Battery Pricing — kept unchanged from the original 2025 file
A2: Provided for reference / CAPEX calculations. Currency: EUR, as in the original file.
A4: Item | B4: Unit Price | C4: Unit | D4: Note
A5: Solar panel | B5: ='Sources & Methodology'!B9 -> 1200 | C5: €/kWp | D5: Linked from Sources & Methodology sheet — original 2025 file value, not modified.
A6: Battery (Li-ion) | B6: ='Sources & Methodology'!B10 -> 400 | C6: €/kWh | D6: Linked from Sources & Methodology sheet — original 2025 file value, not modified.
